{"name": "Login to TMS-CaseManager and view all alerts in Common Queue1", "status": "broken", "statusDetails": {"message": "requests.exceptions.ConnectionError: HTTPSConnectionPool(host='atoms-api-devv.solyticspartners.com', port=443): Max retries exceeded with url: /api/v1/qa/atoms/case-manager/filters/data/?page=1&page_size=5 (Caused by NameResolutionError(\"<urllib3.connection.HTTPSConnection object at 0x00000188BA522D50>: Failed to resolve 'atoms-api-devv.solyticspartners.com' ([Errno 11001] getaddrinfo failed)\"))\n", "trace": "  File \"C:\\Users\\SHRINIDHI\\AppData\\Local\\Programs\\Python\\Python313\\Lib\\site-packages\\behave\\model.py\", line 1329, in run\n    match.run(runner.context)\n    ~~~~~~~~~^^^^^^^^^^^^^^^^\n  File \"C:\\Users\\SHRINIDHI\\AppData\\Local\\Programs\\Python\\Python313\\Lib\\site-packages\\behave\\matchers.py\", line 98, in run\n    self.func(context, *args, **kwargs)\n    ~~~~~~~~~^^^^^^^^^^^^^^^^^^^^^^^^^^\n  File \"TMS-CaseManager\\features\\steps\\case_steps.py\", line 29, in step_impl2\n    context.response = context.api.TestApi(\"POST\", context.token, endpoint, payload=payload)\n                       ~~~~~~~~~~~~~~~~~~~^^^^^^^^^^^^^^^^^^^^^^^^^^^^^^^^^^^^^^^^^^^^^^^^^^\n  File \"C:\\Users\\SHRINIDHI\\OneDrive\\TMS-CaseManager API\\TMS-CaseManager\\utils\\common\\api_helper.py\", line 46, in TestApi\n    return requests.post(\n           ~~~~~~~~~~~~~^\n        self.URL + endPoint,\n        ^^^^^^^^^^^^^^^^^^^^\n        headers=headers,\n        ^^^^^^^^^^^^^^^^\n        json=payload,\n        ^^^^^^^^^^^^^\n    )\n    ^\n  File \"C:\\Users\\SHRINIDHI\\AppData\\Local\\Programs\\Python\\Python313\\Lib\\site-packages\\requests\\api.py\", line 115, in post\n    return request(\"post\", url, data=data, json=json, **kwargs)\n  File \"C:\\Users\\SHRINIDHI\\AppData\\Local\\Programs\\Python\\Python313\\Lib\\site-packages\\requests\\api.py\", line 59, in request\n    return session.request(method=method, url=url, **kwargs)\n           ~~~~~~~~~~~~~~~^^^^^^^^^^^^^^^^^^^^^^^^^^^^^^^^^^\n  File \"C:\\Users\\SHRINIDHI\\AppData\\Local\\Programs\\Python\\Python313\\Lib\\site-packages\\requests\\sessions.py\", line 589, in request\n    resp = self.send(prep, **send_kwargs)\n  File \"C:\\Users\\SHRINIDHI\\AppData\\Local\\Programs\\Python\\Python313\\Lib\\site-packages\\requests\\sessions.py\", line 703, in send\n    r = adapter.send(request, **kwargs)\n  File \"C:\\Users\\SHRINIDHI\\AppData\\Local\\Programs\\Python\\Python313\\Lib\\site-packages\\requests\\adapters.py\", line 700, in send\n    raise ConnectionError(e, request=request)\n"}, "description": "Tags: []", "steps": [{"name": "Given the user is logged in to TMS-CaseManager", "status": "passed", "steps": [{"name": "the user is logged in to TMS-CaseManager", "status": "passed", "start": 1756192815215, "stop": 1756192816189}], "start": 1756192815215, "stop": 1756192816189}, {"name": "When the user navigates to the Common Queue", "status": "broken", "statusDetails": {"message": "requests.exceptions.ConnectionError: HTTPSConnectionPool(host='atoms-api-devv.solyticspartners.com', port=443): Max retries exceeded with url: /api/v1/qa/atoms/case-manager/filters/data/?page=1&page_size=5 (Caused by NameResolutionError(\"<urllib3.connection.HTTPSConnection object at 0x00000188BA522D50>: Failed to resolve 'atoms-api-devv.solyticspartners.com' ([Errno 11001] getaddrinfo failed)\"))\n", "trace": "  File \"C:\\Users\\SHRINIDHI\\AppData\\Local\\Programs\\Python\\Python313\\Lib\\site-packages\\behave\\model.py\", line 1329, in run\n    match.run(runner.context)\n    ~~~~~~~~~^^^^^^^^^^^^^^^^\n  File \"C:\\Users\\SHRINIDHI\\AppData\\Local\\Programs\\Python\\Python313\\Lib\\site-packages\\behave\\matchers.py\", line 98, in run\n    self.func(context, *args, **kwargs)\n    ~~~~~~~~~^^^^^^^^^^^^^^^^^^^^^^^^^^\n  File \"TMS-CaseManager\\features\\steps\\case_steps.py\", line 29, in step_impl2\n    context.response = context.api.TestApi(\"POST\", context.token, endpoint, payload=payload)\n                       ~~~~~~~~~~~~~~~~~~~^^^^^^^^^^^^^^^^^^^^^^^^^^^^^^^^^^^^^^^^^^^^^^^^^^\n  File \"C:\\Users\\SHRINIDHI\\OneDrive\\TMS-CaseManager API\\TMS-CaseManager\\utils\\common\\api_helper.py\", line 46, in TestApi\n    return requests.post(\n           ~~~~~~~~~~~~~^\n        self.URL + endPoint,\n        ^^^^^^^^^^^^^^^^^^^^\n        headers=headers,\n        ^^^^^^^^^^^^^^^^\n        json=payload,\n        ^^^^^^^^^^^^^\n    )\n    ^\n  File \"C:\\Users\\SHRINIDHI\\AppData\\Local\\Programs\\Python\\Python313\\Lib\\site-packages\\requests\\api.py\", line 115, in post\n    return request(\"post\", url, data=data, json=json, **kwargs)\n  File \"C:\\Users\\SHRINIDHI\\AppData\\Local\\Programs\\Python\\Python313\\Lib\\site-packages\\requests\\api.py\", line 59, in request\n    return session.request(method=method, url=url, **kwargs)\n           ~~~~~~~~~~~~~~~^^^^^^^^^^^^^^^^^^^^^^^^^^^^^^^^^^\n  File \"C:\\Users\\SHRINIDHI\\AppData\\Local\\Programs\\Python\\Python313\\Lib\\site-packages\\requests\\sessions.py\", line 589, in request\n    resp = self.send(prep, **send_kwargs)\n  File \"C:\\Users\\SHRINIDHI\\AppData\\Local\\Programs\\Python\\Python313\\Lib\\site-packages\\requests\\sessions.py\", line 703, in send\n    r = adapter.send(request, **kwargs)\n  File \"C:\\Users\\SHRINIDHI\\AppData\\Local\\Programs\\Python\\Python313\\Lib\\site-packages\\requests\\adapters.py\", line 700, in send\n    raise ConnectionError(e, request=request)\n"}, "steps": [{"name": "the user navigates to the Common Queue", "status": "broken", "statusDetails": {"message": "requests.exceptions.ConnectionError: HTTPSConnectionPool(host='atoms-api-devv.solyticspartners.com', port=443): Max retries exceeded with url: /api/v1/qa/atoms/case-manager/filters/data/?page=1&page_size=5 (Caused by NameResolutionError(\"<urllib3.connection.HTTPSConnection object at 0x00000188BA522D50>: Failed to resolve 'atoms-api-devv.solyticspartners.com' ([Errno 11001] getaddrinfo failed)\"))\n", "trace": "  File \"C:\\Users\\SHRINIDHI\\AppData\\Local\\Programs\\Python\\Python313\\Lib\\site-packages\\behave\\model.py\", line 1329, in run\n    match.run(runner.context)\n    ~~~~~~~~~^^^^^^^^^^^^^^^^\n  File \"C:\\Users\\SHRINIDHI\\AppData\\Local\\Programs\\Python\\Python313\\Lib\\site-packages\\behave\\matchers.py\", line 98, in run\n    self.func(context, *args, **kwargs)\n    ~~~~~~~~~^^^^^^^^^^^^^^^^^^^^^^^^^^\n  File \"TMS-CaseManager\\features\\steps\\case_steps.py\", line 29, in step_impl2\n    context.response = context.api.TestApi(\"POST\", context.token, endpoint, payload=payload)\n                       ~~~~~~~~~~~~~~~~~~~^^^^^^^^^^^^^^^^^^^^^^^^^^^^^^^^^^^^^^^^^^^^^^^^^^\n  File \"C:\\Users\\SHRINIDHI\\OneDrive\\TMS-CaseManager API\\TMS-CaseManager\\utils\\common\\api_helper.py\", line 46, in TestApi\n    return requests.post(\n           ~~~~~~~~~~~~~^\n        self.URL + endPoint,\n        ^^^^^^^^^^^^^^^^^^^^\n        headers=headers,\n        ^^^^^^^^^^^^^^^^\n        json=payload,\n        ^^^^^^^^^^^^^\n    )\n    ^\n  File \"C:\\Users\\SHRINIDHI\\AppData\\Local\\Programs\\Python\\Python313\\Lib\\site-packages\\requests\\api.py\", line 115, in post\n    return request(\"post\", url, data=data, json=json, **kwargs)\n  File \"C:\\Users\\SHRINIDHI\\AppData\\Local\\Programs\\Python\\Python313\\Lib\\site-packages\\requests\\api.py\", line 59, in request\n    return session.request(method=method, url=url, **kwargs)\n           ~~~~~~~~~~~~~~~^^^^^^^^^^^^^^^^^^^^^^^^^^^^^^^^^^\n  File \"C:\\Users\\SHRINIDHI\\AppData\\Local\\Programs\\Python\\Python313\\Lib\\site-packages\\requests\\sessions.py\", line 589, in request\n    resp = self.send(prep, **send_kwargs)\n  File \"C:\\Users\\SHRINIDHI\\AppData\\Local\\Programs\\Python\\Python313\\Lib\\site-packages\\requests\\sessions.py\", line 703, in send\n    r = adapter.send(request, **kwargs)\n  File \"C:\\Users\\SHRINIDHI\\AppData\\Local\\Programs\\Python\\Python313\\Lib\\site-packages\\requests\\adapters.py\", line 700, in send\n    raise ConnectionError(e, request=request)\n"}, "attachments": [{"name": "Error in step: the user navigates to the Common Queue", "source": "b2f1dc9c-86dd-4fcc-b55a-13dadf516458-attachment.txt", "type": "text/plain"}], "start": 1756192816189, "stop": 1756192816195}], "start": 1756192816189, "stop": 1756192816198}, {"name": "Then the system should display all alerts with Alert ID and Transaction Type", "status": "skipped", "start": 1756192816204, "stop": 1756192816204}, {"name": "Then Investigate one of the case", "status": "skipped", "start": 1756192816204, "stop": 1756192816204}], "attachments": [{"name": "Failure in step: the user navigates to the Common Queue", "source": "5392a813-f7ca-4500-94b4-0d844f7b7a1b-attachment.txt", "type": "text/plain"}], "start": 1756192815214, "stop": 1756192816204, "uuid": "4ab0ceb4-2180-402e-bceb-6d43b1843183", "historyId": "5f0a781f665c67260d1a950a34b9a4c4", "fullName": "View Alerts in Common Queue: Login to TMS-CaseManager and view all alerts in Common Queue1", "labels": [{"name": "severity", "value": "normal"}, {"name": "feature", "value": "View Alerts in Common Queue"}, {"name": "framework", "value": "behave"}, {"name": "language", "value": "cpython3"}]}